<?xml version="1.0" ?>
<!-- =================================================================================== -->
<!-- |    This document was autogenerated by xacro from crane_plus.urdf.xacro          | -->
<!-- |    EDITING THIS FILE BY HAND IS NOT RECOMMENDED                                 | -->
<!-- =================================================================================== -->
<robot name="crane_plus" xmlns:controller="http://playerstage.sourceforge.net/gazebo/xmlschema/#controller" xmlns:interface="http://playerstage.sourceforge.net/gazebo/xmlschema/#interface" xmlns:sensor="http://playerstage.sourceforge.net/gazebo/xmlschema/#sensor" xmlns:xacro="http://ros.org/wiki/xacro">
  <material name="grey">
    <color rgba="0.75 0.75 0.75 1.0"/>
  </material>
  <material name="black">
    <color rgba="0.2 0.2 0.2 1.0"/>
  </material>
  <!-- Link to provide the location reference for the arm -->
  <link name="base_link"/>
  <link name="crane_plus_mounting_link"/>
  <joint name="crane_plus_mounting_joint" type="fixed">
    <origin xyz="0 0 0"/>
    <parent link="base_link"/>
    <child link="crane_plus_mounting_link"/>
  </joint>
  <!-- TODO: When rviz supports multiple materials per link, combine the
         meshes to simplify the link structure. -->
  <joint name="crane_plus_internal_mounting_plate_joint" type="fixed">
    <origin rpy="0 0 0" xyz="0 0 0"/>
    <parent link="crane_plus_mounting_link"/>
    <child link="crane_plus_internal_mounting_plate_link"/>
  </joint>
  <link name="crane_plus_internal_mounting_plate_link">
    <!--<inertial>-->
    <!--<mass value="0.02"/>-->
    <!--<origin xyz="0 0 0.0005" rpy="0 0 0"/>-->
    <!--<inertia ixx="4.1683e-6" ixy="0.0" ixz="0.0"-->
    <!--iyy="8.33e-6" iyz="0.0"-->
    <!--izz="4.1683e-6"/>-->
    <!--</inertial>-->
    <inertial>
      <mass value="0.001"/>
      <origin rpy="0 0 0" xyz="0 0 0.0005"/>
      <inertia ixx="1" ixy="0.0" ixz="0.0" iyy="1" iyz="0.0" izz="1"/>
    </inertial>
    <visual>
      <origin rpy="0 0 0" xyz="-0.025 -0.025 0"/>
      <geometry>
        <mesh filename="package://crane_plus_description/meshes/mount.stl" scale="1 1 1"/>
      </geometry>
      <material name="black"/>
    </visual>
    <collision>
      <origin rpy="0 0 0" xyz="0 0 0.0005"/>
      <geometry>
        <box size="0.05 0.05 0.001"/>
      </geometry>
    </collision>
  </link>
  <joint name="crane_plus_internal_base_bracket_joint" type="fixed">
    <origin rpy="0 0 0" xyz="0 0 0.001"/>
    <parent link="crane_plus_internal_mounting_plate_link"/>
    <child link="crane_plus_internal_base_bracket_link"/>
  </joint>
  <link name="crane_plus_internal_base_bracket_link">
    <inertial>
      <mass value="0.001"/>
      <origin rpy="0 0 0" xyz="0 0 0.0005"/>
      <inertia ixx="1" ixy="0.0" ixz="0.0" iyy="1" iyz="0.0" izz="1"/>
    </inertial>
    <!--<inertial>-->
    <!--<mass value="0.005"/>-->
    <!--<origin xyz="0.0 0.0 0.004" rpy="0 0 0"/>-->
    <!--<inertia ixx="4.53e-7" ixy="0.0" ixz="0.0"-->
    <!--iyy="6.283e-7" iyz="0.0"-->
    <!--izz="2.283e-7"/>-->
    <!--</inertial>-->
    <visual>
      <origin rpy="-1.570795 0 0" xyz="0 0 0"/>
      <geometry>
        <mesh filename="package://crane_plus_description/meshes/f53.stl" scale="0.01 0.01 0.01"/>
      </geometry>
      <material name="grey"/>
    </visual>
    <collision>
      <origin rpy="0 0 0" xyz="0.0 0.0 0.004"/>
      <geometry>
        <box size="0.022 0.032 0.008"/>
      </geometry>
    </collision>
  </link>
  <joint name="crane_plus_internal_shoulder_servo_joint" type="fixed">
    <origin rpy="0 0 0" xyz="-0.0028 0 0.023"/>
    <parent link="crane_plus_internal_base_bracket_link"/>
    <child link="crane_plus_internal_shoulder_servo_link"/>
  </joint>
  <link name="crane_plus_internal_shoulder_servo_link">
    <inertial>
      <mass value="0.001"/>
      <origin rpy="0 0 0" xyz="0 0 0.0005"/>
      <inertia ixx="1" ixy="0.0" ixz="0.0" iyy="1" iyz="0.0" izz="1"/>
    </inertial>
    <!--<inertial>-->
    <!--<mass value="0.0564"/>-->
    <!--<origin xyz="${0-AX12_ORIGIN_OFFSET_X} 0 0" rpy="0 0 0"/>-->
    <!--<inertia ixx="1.16e-5" ixy="0.0" ixz="0.0"-->
    <!--iyy="1.656e-50" iyz="0.0"-->
    <!--izz="1.854e-5"/>-->
    <!--</inertial>-->
    <visual>
      <origin rpy="-1.570795 0 0" xyz="0 0 0"/>
      <geometry>
        <mesh filename="package://crane_plus_description/meshes/ax12_box.stl" scale="0.001 0.001 0.001"/>
      </geometry>
      <material name="black"/>
    </visual>
    <collision>
      <origin rpy="0 0 0" xyz="0.0015 0 0"/>
      <geometry>
        <box size="0.05 0.032 0.038"/>
      </geometry>
    </collision>
  </link>
  <joint name="crane_plus_shoulder_revolute_joint" type="revolute">
    <origin rpy="0 0 0" xyz="-0.0135 0 0.021"/>
    <axis xyz="0 0 1"/>
    <limit effort="30" lower="-2.617" upper="2.617" velocity="1.571"/>
    <parent link="crane_plus_internal_shoulder_servo_link"/>
    <child link="crane_plus_shoulder_revolute_link"/>
  </joint>
  <link name="crane_plus_shoulder_revolute_link">
    <inertial>
      <mass value="0.001"/>
      <origin rpy="0 0 0" xyz="0 0 0.0005"/>
      <inertia ixx="1" ixy="0.0" ixz="0.0" iyy="1" iyz="0.0" izz="1"/>
    </inertial>
    <!--<inertial>-->
    <!--<mass value="0.01"/>-->
    <!--<origin xyz="0 0 0.01875" rpy="0 0 0"/>-->
    <!--[> Full height: (3.1320833333333333e-06, 2.481041666666667e-06, 1.6927083333333333e-06) <]-->
    <!--[> Half height: (2.253177083333333e-06, 2.481041666666667e-06, 8.138020833333333e-07) <]-->
    <!--<inertia ixx="2.253e-6" ixy="0.0" ixz="0.0"-->
    <!--iyy="2.481e-6" iyz="0.0"-->
    <!--izz="8.138e-7"/>-->
    <!--</inertial>-->
    <visual>
      <origin rpy="1.570795 0 0" xyz="0 0 0.0265"/>
      <geometry>
        <mesh filename="package://crane_plus_description/meshes/f2.stl" scale="0.001 0.001 0.001"/>
      </geometry>
      <material name="grey"/>
    </visual>
    <collision>
      <origin rpy="0 0 0" xyz="0 0 0.01875"/>
      <geometry>
        <box size="0.025 0.0485 0.0375"/>
      </geometry>
    </collision>
  </link>
  <joint name="crane_plus_shoulder_flex_joint" type="revolute">
    <origin rpy="-1.570795 -1.570795 0" xyz="0 0 0.0265"/>
    <axis xyz="0 0 -1"/>
    <limit effort="30" lower="-1.7" upper="1.7" velocity="1.571"/>
    <parent link="crane_plus_shoulder_revolute_link"/>
    <child link="crane_plus_shoulder_flex_link"/>
  </joint>
  <link name="crane_plus_shoulder_flex_link">
    <inertial>
      <mass value="0.001"/>
      <origin rpy="0 0 0" xyz="0 0 0.0005"/>
      <inertia ixx="1" ixy="0.0" ixz="0.0" iyy="1" iyz="0.0" izz="1"/>
    </inertial>
    <!--<inertial>-->
    <!--<mass value="0.0564"/>-->
    <!--<origin xyz="${AX12_ORIGIN_TO_AXLE-AX12_ORIGIN_OFFSET_X} 0 0" rpy="0 0 0"/>-->
    <!--<inertia ixx="1.16e-5" ixy="0.0" ixz="0.0"-->
    <!--iyy="1.656e-5" iyz="0.0"-->
    <!--izz="1.854e-5"/>-->
    <!--</inertial>-->
    <visual>
      <origin rpy="-1.570795 0 0" xyz="0.012 0 0"/>
      <geometry>
        <mesh filename="package://crane_plus_description/meshes/ax12_box.stl" scale="0.001 0.001 0.001"/>
      </geometry>
      <material name="black"/>
    </visual>
    <collision>
      <origin rpy="0 0 0" xyz="0.0135 0 0"/>
      <geometry>
        <box size="0.05 0.032 0.038"/>
      </geometry>
    </collision>
  </link>
  <joint name="crane_plus_internal_upper_arm_upper_joiner_joint" type="fixed">
    <origin rpy="-1.570795 0 1.570795" xyz="0.0415 0 0"/>
    <parent link="crane_plus_shoulder_flex_link"/>
    <child link="crane_plus_internal_upper_arm_upper_joiner_link"/>
  </joint>
  <link name="crane_plus_internal_upper_arm_upper_joiner_link">
    <inertial>
      <mass value="0.001"/>
      <origin rpy="0 0 0" xyz="0 0 0.0005"/>
      <inertia ixx="1" ixy="0.0" ixz="0.0" iyy="1" iyz="0.0" izz="1"/>
    </inertial>
    <!--<inertial>-->
    <!--<mass value="0.005"/>-->
    <!--<origin xyz="0.0 0.0 0.0045" rpy="0 0 0"/>-->
    <!--<inertia ixx="6.354e-7" ixy="0.0" ixz="0.0"-->
    <!--iyy="8.621e-7" iyz="0.0"-->
    <!--izz="2.942e-7"/>-->
    <!--</inertial>-->
    <visual>
      <origin rpy="1.570795 0 3.14159" xyz="0 0 0"/>
      <geometry>
        <mesh filename="package://crane_plus_description/meshes/f3.stl" scale="0.001 0.001 0.001"/>
      </geometry>
      <material name="grey"/>
    </visual>
    <collision>
      <origin rpy="0 0 0" xyz="0.0 0.0 0.0045"/>
      <geometry>
        <box size="0.025 0.038 0.009"/>
      </geometry>
    </collision>
  </link>
  <joint name="crane_plus_internal_upper_arm_lower_joiner_joint" type="fixed">
    <origin rpy="3.14159 0 0" xyz="0 0 0"/>
    <parent link="crane_plus_internal_upper_arm_upper_joiner_link"/>
    <child link="crane_plus_internal_upper_arm_lower_joiner_link"/>
  </joint>
  <link name="crane_plus_internal_upper_arm_lower_joiner_link">
    <inertial>
      <mass value="0.001"/>
      <origin rpy="0 0 0" xyz="0 0 0.0005"/>
      <inertia ixx="1" ixy="0.0" ixz="0.0" iyy="1" iyz="0.0" izz="1"/>
    </inertial>
    <!--<inertial>-->
    <!--<mass value="0.005"/>-->
    <!--<origin xyz="0.0 0.0 0.0045" rpy="0 0 0"/>-->
    <!--<inertia ixx="6.354e-7" ixy="0.0" ixz="0.0"-->
    <!--iyy="8.621e-7" iyz="0.0"-->
    <!--izz="2.942e-7"/>-->
    <!--</inertial>-->
    <visual>
      <origin rpy="1.570795 0 3.14159" xyz="0 0 0"/>
      <geometry>
        <mesh filename="package://crane_plus_description/meshes/f3.stl" scale="0.001 0.001 0.001"/>
      </geometry>
      <material name="grey"/>
    </visual>
    <collision>
      <origin rpy="0 0 0" xyz="0.0 0.0 0.0045"/>
      <geometry>
        <box size="0.025 0.038 0.009"/>
      </geometry>
    </collision>
  </link>
  <joint name="crane_plus_internal_lower_arm_servo_joint" type="fixed">
    <origin rpy="0 1.570795 1.570795" xyz="0 0 0.0295"/>
    <parent link="crane_plus_internal_upper_arm_lower_joiner_link"/>
    <child link="crane_plus_internal_lower_arm_servo_link"/>
  </joint>
  <link name="crane_plus_internal_lower_arm_servo_link">
    <inertial>
      <mass value="0.001"/>
      <origin rpy="0 0 0" xyz="0 0 0.0005"/>
      <inertia ixx="1" ixy="0.0" ixz="0.0" iyy="1" iyz="0.0" izz="1"/>
    </inertial>
    <!--<inertial>-->
    <!--<mass value="0.0564"/>-->
    <!--<origin xyz="${0-AX12_ORIGIN_OFFSET_X} 0 0" rpy="0 0 0"/>-->
    <!--<inertia ixx="1.16e-5" ixy="0.0" ixz="0.0"-->
    <!--iyy="1.656e-50" iyz="0.0"-->
    <!--izz="1.854e-5"/>-->
    <!--</inertial>-->
    <visual>
      <origin rpy="-1.570795 0 0" xyz="0 0 0"/>
      <geometry>
        <mesh filename="package://crane_plus_description/meshes/ax12_box.stl" scale="0.001 0.001 0.001"/>
      </geometry>
      <material name="black"/>
    </visual>
    <collision>
      <origin rpy="0 0 0" xyz="0.0015 0 0"/>
      <geometry>
        <box size="0.05 0.032 0.038"/>
      </geometry>
    </collision>
  </link>
  <joint name="crane_plus_elbow_joint" type="revolute">
    <origin rpy="1.570795 0 1.570795" xyz="-0.012 0 0"/>
    <axis xyz="0 1 0"/>
    <limit effort="30" lower="-2.3" upper="2.3" velocity="1.571"/>
    <parent link="crane_plus_internal_lower_arm_servo_link"/>
    <child link="crane_plus_elbow_link"/>
  </joint>
  <link name="crane_plus_elbow_link">
    <inertial>
      <mass value="0.001"/>
      <origin rpy="0 0 0" xyz="0 0 0.0005"/>
      <inertia ixx="1" ixy="0.0" ixz="0.0" iyy="1" iyz="0.0" izz="1"/>
    </inertial>
    <!--<inertial>-->
    <!--<mass value="0.015"/>-->
    <!--<origin xyz="0 0 -${F4_AXLE_HEIGHT-F4_HEIGHT/2+0.0015}" rpy="0 0 0"/>-->
    <!--[> Full height: (8.2215625e-06, 3.9203124999999996e-06, 6.2612499999999996e-06) <]-->
    <!--[> Half height: (4.2606249999999995e-06, 3.9203124999999996e-06, 2.3003125e-06) <]-->
    <!--<inertia ixx="4.261e-6" ixy="0.0" ixz="0.0"-->
    <!--iyy="3.921e-6" iyz="0.0"-->
    <!--izz="2.3e-6"/>-->
    <!--</inertial>-->
    <visual>
      <origin rpy="1.570795 0 0" xyz="0 0 0"/>
      <geometry>
        <mesh filename="package://crane_plus_description/meshes/f4.stl" scale="0.001 0.001 0.001"/>
      </geometry>
      <material name="grey"/>
    </visual>
    <collision>
      <!-- 0.0015 is for the nub height which is not included in
             F4_AXLE_HEIGHT -->
      <origin rpy="0 0 0" xyz="0 0 -0.0215"/>
      <geometry>
        <box size="0.028 0.0485 0.065"/>
      </geometry>
    </collision>
  </link>
  <joint name="crane_plus_internal_lower_arm_joiner_joint" type="fixed">
    <origin rpy="0 3.14159 0" xyz="0 0 -0.0525"/>
    <parent link="crane_plus_elbow_link"/>
    <child link="crane_plus_internal_lower_arm_joiner_link"/>
  </joint>
  <link name="crane_plus_internal_lower_arm_joiner_link">
    <inertial>
      <mass value="0.001"/>
      <origin rpy="0 0 0" xyz="0 0 0.0005"/>
      <inertia ixx="1" ixy="0.0" ixz="0.0" iyy="1" iyz="0.0" izz="1"/>
    </inertial>
    <!--<inertial>-->
    <!--<mass value="0.005"/>-->
    <!--<origin xyz="0.0 0.0 0.0045" rpy="0 0 0"/>-->
    <!--<inertia ixx="6.354e-7" ixy="0.0" ixz="0.0"-->
    <!--iyy="8.621e-7" iyz="0.0"-->
    <!--izz="2.942e-7"/>-->
    <!--</inertial>-->
    <visual>
      <origin rpy="1.570795 0 3.14159" xyz="0 0 0"/>
      <geometry>
        <mesh filename="package://crane_plus_description/meshes/f3.stl" scale="0.001 0.001 0.001"/>
      </geometry>
      <material name="grey"/>
    </visual>
    <collision>
      <origin rpy="0 0 0" xyz="0.0 0.0 0.0045"/>
      <geometry>
        <box size="0.025 0.038 0.009"/>
      </geometry>
    </collision>
  </link>
  <joint name="crane_plus_internal_wrist_servo_joint" type="fixed">
    <origin rpy="0 1.570795 1.570795" xyz="0 0 0.0295"/>
    <parent link="crane_plus_internal_lower_arm_joiner_link"/>
    <child link="crane_plus_internal_wrist_servo_link"/>
  </joint>
  <link name="crane_plus_internal_wrist_servo_link">
    <inertial>
      <mass value="0.001"/>
      <origin rpy="0 0 0" xyz="0 0 0.0005"/>
      <inertia ixx="1" ixy="0.0" ixz="0.0" iyy="1" iyz="0.0" izz="1"/>
    </inertial>
    <!--<inertial>-->
    <!--<mass value="0.0564"/>-->
    <!--<origin xyz="${0-AX12_ORIGIN_OFFSET_X} 0 0" rpy="0 0 0"/>-->
    <!--<inertia ixx="1.16e-5" ixy="0.0" ixz="0.0"-->
    <!--iyy="1.656e-50" iyz="0.0"-->
    <!--izz="1.854e-5"/>-->
    <!--</inertial>-->
    <visual>
      <origin rpy="-1.570795 0 0" xyz="0 0 0"/>
      <geometry>
        <mesh filename="package://crane_plus_description/meshes/ax12_box.stl" scale="0.001 0.001 0.001"/>
      </geometry>
      <material name="black"/>
    </visual>
    <collision>
      <origin rpy="0 0 0" xyz="0.0015 0 0"/>
      <geometry>
        <box size="0.05 0.032 0.038"/>
      </geometry>
    </collision>
  </link>
  <joint name="crane_plus_wrist_joint" type="revolute">
    <origin rpy="-1.570795 0 -1.570795" xyz="-0.012 0 0"/>
    <axis xyz="0 -1 0"/>
    <limit effort="30" lower="-1.7" upper="1.7" velocity="1.571"/>
    <parent link="crane_plus_internal_wrist_servo_link"/>
    <child link="crane_plus_wrist_link"/>
  </joint>
  <link name="crane_plus_wrist_link">
    <inertial>
      <mass value="0.001"/>
      <origin rpy="0 0 0" xyz="0 0 0.0005"/>
      <inertia ixx="1" ixy="0.0" ixz="0.0" iyy="1" iyz="0.0" izz="1"/>
    </inertial>
    <!--<inertial>-->
    <!--<mass value="0.01"/>-->
    <!--<origin xyz="0 0 -${F2_AXLE_HEIGHT-F2_HEIGHT/2}" rpy="0 0 0"/>-->
    <!--[> Full height: (3.1320833333333333e-06, 2.481041666666667e-06, 1.6927083333333333e-06) <]-->
    <!--[> Half height: (2.253177083333333e-06, 2.481041666666667e-06, 8.138020833333333e-07) <]-->
    <!--<inertia ixx="2.253e-6" ixy="0.0" ixz="0.0"-->
    <!--iyy="2.481e-6" iyz="0.0"-->
    <!--izz="8.138e-7"/>-->
    <!--</inertial>-->
    <visual>
      <origin rpy="1.570795 0 0" xyz="0 0 0"/>
      <geometry>
        <mesh filename="package://crane_plus_description/meshes/f2.stl" scale="0.001 0.001 0.001"/>
      </geometry>
      <material name="grey"/>
    </visual>
    <collision>
      <origin rpy="0 0 0" xyz="0 0 -0.00775"/>
      <geometry>
        <box size="0.025 0.0485 0.0375"/>
      </geometry>
    </collision>
  </link>
  <joint name="crane_plus_internal_wrist_joiner_joint" type="fixed">
    <origin rpy="0 3.14159 1.570795" xyz="0 0 -0.0265"/>
    <parent link="crane_plus_wrist_link"/>
    <child link="crane_plus_internal_wrist_joiner_link"/>
  </joint>
  <link name="crane_plus_internal_wrist_joiner_link">
    <inertial>
      <mass value="0.001"/>
      <origin rpy="0 0 0" xyz="0 0 0.0005"/>
      <inertia ixx="1" ixy="0.0" ixz="0.0" iyy="1" iyz="0.0" izz="1"/>
    </inertial>
    <!--<inertial>-->
    <!--<mass value="0.005"/>-->
    <!--<origin xyz="0.0 0.0 0.0045" rpy="0 0 0"/>-->
    <!--<inertia ixx="6.354e-7" ixy="0.0" ixz="0.0"-->
    <!--iyy="8.621e-7" iyz="0.0"-->
    <!--izz="2.942e-7"/>-->
    <!--</inertial>-->
    <visual>
      <origin rpy="1.570795 0 3.14159" xyz="0 0 0"/>
      <geometry>
        <mesh filename="package://crane_plus_description/meshes/f3.stl" scale="0.001 0.001 0.001"/>
      </geometry>
      <material name="grey"/>
    </visual>
    <collision>
      <origin rpy="0 0 0" xyz="0.0 0.0 0.0045"/>
      <geometry>
        <box size="0.025 0.038 0.009"/>
      </geometry>
    </collision>
  </link>
  <joint name="crane_plus_internal_gripper_servo_joint" type="fixed">
    <origin rpy="1.570795 3.14159 0" xyz="0.0028 0 0.019"/>
    <parent link="crane_plus_internal_wrist_joiner_link"/>
    <child link="crane_plus_internal_gripper_servo_link"/>
  </joint>
  <link name="crane_plus_internal_gripper_servo_link">
    <inertial>
      <mass value="0.001"/>
      <origin rpy="0 0 0" xyz="0 0 0.0005"/>
      <inertia ixx="1" ixy="0.0" ixz="0.0" iyy="1" iyz="0.0" izz="1"/>
    </inertial>
    <!--<inertial>-->
    <!--<mass value="0.0564"/>-->
    <!--<origin xyz="${0-AX12_ORIGIN_OFFSET_X} 0 0" rpy="0 0 0"/>-->
    <!--<inertia ixx="1.16e-5" ixy="0.0" ixz="0.0"-->
    <!--iyy="1.656e-50" iyz="0.0"-->
    <!--izz="1.854e-5"/>-->
    <!--</inertial>-->
    <visual>
      <origin rpy="-1.570795 0 0" xyz="0 0 0"/>
      <geometry>
        <mesh filename="package://crane_plus_description/meshes/ax12_box.stl" scale="0.001 0.001 0.001"/>
      </geometry>
      <material name="black"/>
    </visual>
    <collision>
      <origin rpy="0 0 0" xyz="0.0015 0 0"/>
      <geometry>
        <box size="0.05 0.032 0.038"/>
      </geometry>
    </collision>
  </link>
  <joint name="crane_plus_internal_fixed_finger_joiner_joint" type="fixed">
    <origin rpy="-1.570795 0 1.570795" xyz="0.0295 0 0"/>
    <parent link="crane_plus_internal_gripper_servo_link"/>
    <child link="crane_plus_internal_fixed_finger_joiner_link"/>
  </joint>
  <link name="crane_plus_internal_fixed_finger_joiner_link">
    <inertial>
      <mass value="0.001"/>
      <origin rpy="0 0 0" xyz="0 0 0.0005"/>
      <inertia ixx="1" ixy="0.0" ixz="0.0" iyy="1" iyz="0.0" izz="1"/>
    </inertial>
    <!--<inertial>-->
    <!--<mass value="0.005"/>-->
    <!--<origin xyz="0.0 0.0 0.0045" rpy="0 0 0"/>-->
    <!--<inertia ixx="6.354e-7" ixy="0.0" ixz="0.0"-->
    <!--iyy="8.621e-7" iyz="0.0"-->
    <!--izz="2.942e-7"/>-->
    <!--</inertial>-->
    <visual>
      <origin rpy="1.570795 0 3.14159" xyz="0 0 0"/>
      <geometry>
        <mesh filename="package://crane_plus_description/meshes/f3.stl" scale="0.001 0.001 0.001"/>
      </geometry>
      <material name="grey"/>
    </visual>
    <collision>
      <origin rpy="0 0 0" xyz="0.0 0.0 0.0045"/>
      <geometry>
        <box size="0.025 0.038 0.009"/>
      </geometry>
    </collision>
  </link>
  <joint name="crane_plus_internal_fixed_finger_joint" type="fixed">
    <origin rpy="0 0 3.14159" xyz="0 0 0"/>
    <parent link="crane_plus_internal_fixed_finger_joiner_link"/>
    <child link="crane_plus_internal_fixed_finger_link"/>
  </joint>
  <link name="crane_plus_internal_fixed_finger_link">
    <inertial>
      <mass value="0.001"/>
      <origin rpy="0 0 0" xyz="0 0 0.0005"/>
      <inertia ixx="1" ixy="0.0" ixz="0.0" iyy="1" iyz="0.0" izz="1"/>
    </inertial>
    <!--<inertial>-->
    <!--<mass value="0.02"/>-->
    <!--<origin xyz="0 0 0" rpy="0 0 0"/>-->
    <!--<inertia ixx="1.612e-5" ixy="0.0" ixz="0.0"-->
    <!--iyy="1.823e-5" iyz="0.0"-->
    <!--izz="2.732e-6"/>-->
    <!--</inertial>-->
    <visual>
      <origin rpy="0 0 0" xyz="0 0 0"/>
      <geometry>
        <mesh filename="package://crane_plus_description/meshes/finger_fixed.stl" scale="0.001 0.001 0.001"/>
      </geometry>
      <material name="black"/>
    </visual>
    <collision>
      <origin rpy="0 0 0" xyz="0 0 0"/>
      <geometry>
        <mesh filename="package://crane_plus_description/meshes/finger_fixed_collision.stl" scale="0.001 0.001 0.001"/>
      </geometry>
    </collision>
  </link>
  <!-- Tip of the fixed finger (useful in all sorts of ways) -->
  <joint name="crane_plus_fixed_finger_tip" type="fixed">
    <origin rpy="1.570795 0 1.570795" xyz="0.0745 0 -0.0106"/>
    <parent link="crane_plus_internal_fixed_finger_link"/>
    <child link="crane_plus_fixed_finger_tip_link"/>
  </joint>
  <link name="crane_plus_fixed_finger_tip_link"/>
  <joint name="crane_plus_moving_finger_joint" type="revolute">
    <origin rpy="-1.570795 0 -1.570795" xyz="-0.012 0 0"/>
    <axis xyz="0 -1 0"/>
    <limit effort="30" lower="-0.6" upper="0.65" velocity="1.571"/>
    <parent link="crane_plus_internal_gripper_servo_link"/>
    <child link="crane_plus_moving_finger_link"/>
  </joint>
  <link name="crane_plus_moving_finger_link">
    <inertial>
      <mass value="0.001"/>
      <origin rpy="0 0 0" xyz="0 0 0.0005"/>
      <inertia ixx="1" ixy="0.0" ixz="0.0" iyy="1" iyz="0.0" izz="1"/>
    </inertial>
    <!--<inertial>-->
    <!--<mass value="0.01"/>-->
    <!--<origin xyz="0 0 -${F2_AXLE_HEIGHT-F2_HEIGHT/2}" rpy="0 0 0"/>-->
    <!--[> Full height: (3.1320833333333333e-06, 2.481041666666667e-06, 1.6927083333333333e-06) <]-->
    <!--[> Half height: (2.253177083333333e-06, 2.481041666666667e-06, 8.138020833333333e-07) <]-->
    <!--<inertia ixx="2.253e-6" ixy="0.0" ixz="0.0"-->
    <!--iyy="2.481e-6" iyz="0.0"-->
    <!--izz="8.138e-7"/>-->
    <!--</inertial>-->
    <visual>
      <origin rpy="1.570795 0 0" xyz="0 0 0"/>
      <geometry>
        <mesh filename="package://crane_plus_description/meshes/f2.stl" scale="0.001 0.001 0.001"/>
      </geometry>
      <material name="grey"/>
    </visual>
    <collision>
      <origin rpy="0 0 0" xyz="0 0 -0.00775"/>
      <geometry>
        <box size="0.025 0.0485 0.0375"/>
      </geometry>
    </collision>
  </link>
  <joint name="crane_plus_internal_moving_finger_plate_joint" type="fixed">
    <origin rpy="3.14159 0 0" xyz="0 0 -0.0265"/>
    <parent link="crane_plus_moving_finger_link"/>
    <child link="crane_plus_internal_moving_finger_plate_link"/>
  </joint>
  <link name="crane_plus_internal_moving_finger_plate_link">
    <inertial>
      <mass value="0.001"/>
      <origin rpy="0 0 0" xyz="0 0 0.0005"/>
      <inertia ixx="1" ixy="0.0" ixz="0.0" iyy="1" iyz="0.0" izz="1"/>
    </inertial>
    <!--<inertial>-->
    <!--<mass value="0.02"/>-->
    <!--<origin xyz="0 0 0" rpy="0 0 0"/>-->
    <!--<inertia ixx="2.01e-5" ixy="0.0" ixz="0.0"-->
    <!--iyy="2.2e-5" iyz="0.0"-->
    <!--izz="2.936e-6"/>-->
    <!--</inertial>-->
    <visual>
      <origin rpy="0 0 0" xyz="0 0 0"/>
      <geometry>
        <mesh filename="package://crane_plus_description/meshes/finger_moving.stl" scale="0.001 0.001 0.001"/>
      </geometry>
      <material name="black"/>
    </visual>
    <collision>
      <origin rpy="0 0 0" xyz="0 0 0"/>
      <geometry>
        <mesh filename="package://crane_plus_description/meshes/finger_moving_collision.stl" scale="0.001 0.001 0.001"/>
      </geometry>
    </collision>
  </link>
  <!-- Tip of the moving finger (useful in all sorts of ways) -->
  <joint name="crane_plus_moving_finger_tip" type="fixed">
    <origin rpy="1.570795 0 1.570795" xyz="0.0923 0 -0.0194"/>
    <parent link="crane_plus_internal_moving_finger_plate_link"/>
    <child link="crane_plus_moving_finger_tip_link"/>
  </joint>
  <link name="crane_plus_moving_finger_tip_link"/>
  <!-- A virtual link for the gripper to hang off, increasing the degrees of
         freedom by one and making it easier for MoveIt! to plan. -->
  <link name="crane_plus_gripper_link"/>
  <joint name="crane_plus_gripper_joint" type="revolute">
    <origin rpy="0 0 -1.570795" xyz="0 0 0.0537"/>
    <axis xyz="1 0 0"/>
    <parent link="crane_plus_internal_wrist_joiner_link"/>
    <child link="crane_plus_gripper_link"/>
    <limit effort="30" lower="-3.14159" upper="3.14159" velocity="1"/>
  </joint>
</robot>

