<?xml version="1.0"?>
<robot name="crane_plus">
  <link name="base_link">
    <visual>
      <origin xyz="0 0 0.0227" rpy="0 0 0"/>
      <geometry>
        <box size="0.0499 0.032 0.0454"/>
      </geometry>
      <material name="grey">
        <color rgba="0.5 0.5 0.5 1"/>
      </material>
    </visual>
  </link>
  <link name="link1">
    <visual>
      <origin xyz="0 0 0.013" rpy="0 0 0"/>
      <geometry>
        <box size="0.024 0.0475 0.026"/>
      </geometry>
      <material name="grey"/>
    </visual>
    <visual>
      <origin xyz="0 0 0.026" rpy="1.57079632675 0 0"/>
      <geometry>
        <cylinder radius="0.012" length="0.0475"/>
      </geometry>
      <material name="black">
        <color rgba="0.2 0.2 0.2 1"/>
      </material>
    </visual>
  </link>
  <link name="link2">
    <visual>
      <origin xyz="0 0 0" rpy="1.57079632675 0 0"/>
      <geometry>
        <cylinder radius="0.012" length="0.0475"/>
      </geometry>
      <material name="black"/>
    </visual>
    <visual>
      <origin xyz="0 0 0.0415" rpy="0 0 0"/>
      <geometry>
        <box size="0.024 0.0475 0.083"/>
      </geometry>
      <material name="grey"/>
    </visual>
    <visual>
      <origin xyz="0 0 0.083" rpy="1.57079632675 0 0"/>
      <geometry>
        <cylinder radius="0.012" length="0.0475"/>
      </geometry>
      <material name="black"/>
    </visual>
  </link>
  <link name="link3">
    <visual>
      <origin xyz="0 0 0" rpy="1.57079632675 0 0"/>
      <geometry>
        <cylinder radius="0.012" length="0.0475"/>
      </geometry>
      <material name="black"/>
    </visual>
    <visual>
      <origin xyz="0 0 0.04675" rpy="0 0 0"/>
      <geometry>
        <box size="0.024 0.0475 0.0935"/>
      </geometry>
      <material name="grey"/>
    </visual>
    <visual>
      <origin xyz="0 0 0.0935" rpy="1.57079632675 0 0"/>
      <geometry>
        <cylinder radius="0.012" length="0.0475"/>
      </geometry>
      <material name="black"/>
    </visual>
  </link>
  <link name="link4">
    <visual>
      <origin xyz="0 0 0" rpy="1.57079632675 0 0"/>
      <geometry>
        <cylinder radius="0.012" length="0.0475"/>
      </geometry>
      <material name="black"/>
    </visual>
    <visual>
      <origin xyz="0 0 0.0227" rpy="0 0 0"/>
      <geometry>
        <box size="0.024 0.0475 0.061"/>
      </geometry>
      <material name="grey"/>
    </visual>
    <visual>
      <origin xyz="0 0.03295 0.065727241" rpy="-0.52359878 0 0"/>
      <geometry>
        <box size="0.034 0.0014 0.019"/>
      </geometry>
      <material name="grey"/>
    </visual>
    <visual>
      <origin xyz="0 0.0377 0.09665" rpy="0 0 0"/>
      <geometry>
        <box size="0.034 0.0014 0.0454"/>
      </geometry>
      <material name="grey"/>
    </visual>
  </link>
  <link name="link5">
    <visual>
      <origin xyz="0 0 0" rpy="0 1.57079632675 0"/>
      <geometry>
        <cylinder radius="0.012" length="0.0475"/>
      </geometry>
      <material name="black"/>
    </visual>
    <visual>
      <origin xyz="0 -0.013 0" rpy="0 0 0"/>
      <geometry>
        <box size="0.0475 0.026 0.024"/>
      </geometry>
      <material name="grey"/>
    </visual>
    <visual>
      <origin xyz="0 -0.0267 0.023" rpy="0 0 0"/>
      <geometry>
        <box size="0.034 0.0014 0.070"/>
      </geometry>
      <material name="grey"/>
    </visual>
    <visual>
      <origin xyz="0 -0.0166252378 0.07545" rpy="-0.52359878 0 0"/>
      <geometry>
        <box size="0.034 0.0014 0.040299"/>
      </geometry>
      <material name="grey"/>
    </visual>
  </link>

  <joint name="joint1" type="revolute">
    <parent link="base_link"/>
    <child link="link1"/>
    <origin xyz="0.0145 0 0.0454" rpy="0 0 0"/>
    <axis xyz="0 0 1"/>
    <limit lower="-2.61" upper="2.61" effort="0.5" velocity="6.0"/>
  </joint>
  <joint name="joint2" type="revolute">
    <parent link="link1"/>
    <child link="link2"/>
    <origin xyz="0 0 0.026" rpy="0 0 0"/>
    <axis xyz="0 1 0"/>
    <limit lower="-1.75" upper="1.75" effort="0.5" velocity="6.0"/>
  </joint>
  <joint name="joint3" type="revolute">
    <parent link="link2"/>
    <child link="link3"/>
    <origin xyz="0 0 0.083" rpy="0 0 0"/>
    <axis xyz="0 -1 0"/>
    <limit lower="-2.55" upper="2.55" effort="0.5" velocity="6.0"/>
  </joint>
  <joint name="joint4" type="revolute">
    <parent link="link3"/>
    <child link="link4"/>
    <origin xyz="0 0 0.0935" rpy="0 0 0"/>
    <axis xyz="0 -1 0"/>
    <limit lower="-1.80" upper="1.80" effort="0.5" velocity="6.0"/>
  </joint>
  <joint name="joint5" type="revolute">
    <parent link="link4"/>
    <child link="link5"/>
    <origin xyz="0 -0.0145 0.045" rpy="0 0 0"/>
    <axis xyz="-1 0 0"/>
    <limit lower="-0.69" upper="0.69" effort="0.5" velocity="6.0"/>
  </joint>
</robot>
