<?xml version="1.0" ?>
<!-- =================================================================================== -->
<!-- |    This document was autogenerated by xacro from src/crane_plus_arm/crane_plus_description/urdf/crane_plus.urdf.xacro | -->
<!-- |    EDITING THIS FILE BY HAND IS NOT RECOMMENDED                                 | -->
<!-- =================================================================================== -->
<robot name="crane_plus_arm" xmlns:controller="http://playerstage.sourceforge.net/gazebo/xmlschema/#controller" xmlns:interface="http://playerstage.sourceforge.net/gazebo/xmlschema/#interface" xmlns:sensor="http://playerstage.sourceforge.net/gazebo/xmlschema/#sensor" xmlns:xacro="http://ros.org/wiki/xacro">
  <material name="grey">
    <color rgba="0.6 0.6 0.6 1.0"/>
  </material>
  <material name="black">
    <color rgba="0.2 0.2 0.2 1.0"/>
  </material>
  <!-- Link to provide the location reference for the arm -->
  <link name="base_link"/>
  <link name="crane_plus_base_link"/>
  <joint name="crane_plus_base_joint" type="fixed">
    <origin xyz="0 0 0"/>
    <parent link="base_link"/>
    <child link="crane_plus_base_link"/>
  </joint>
  <joint name="crane_plus_mounting_plate_joint" type="fixed">
    <origin rpy="0 0 0" xyz="0 0 0"/>
    <parent link="crane_plus_base_link"/>
    <child link="crane_plus_mounting_plate_link"/>
  </joint>
  <link name="crane_plus_mounting_plate_link">
    <inertial>
      <mass value="0.00001"/>
      <origin xyz="0 0 0"/>
      <inertia ixx="1.0" ixy="0.0" ixz="0.0" iyy="1.0" iyz="0.0" izz="1.0"/>
    </inertial>
    <visual>
      <origin rpy="0 0 0" xyz="-0.025 -0.025 0"/>
      <geometry>
        <mesh filename="package://crane_plus_description/meshes/mount.stl" scale="1 1 1"/>
      </geometry>
      <material name="black"/>
    </visual>
    <collision>
      <origin rpy="0 0 0" xyz="0 0 0.0005"/>
      <geometry>
        <box size="0.05 0.05 0.001"/>
      </geometry>
    </collision>
  </link>
  <joint name="crane_plus_base_bracket_joint" type="fixed">
    <origin rpy="0 0 0" xyz="0 0 0.001"/>
    <parent link="crane_plus_mounting_plate_link"/>
    <child link="crane_plus_base_bracket_link"/>
  </joint>
  <link name="crane_plus_base_bracket_link">
    <inertial>
      <mass value="0.00001"/>
      <origin xyz="0 0 0"/>
      <inertia ixx="1.0" ixy="0.0" ixz="0.0" iyy="1.0" iyz="0.0" izz="1.0"/>
    </inertial>
    <visual>
      <origin rpy="-1.570795 0 0" xyz="0 0 0"/>
      <geometry>
        <mesh filename="package://crane_plus_description/meshes/f53.stl" scale="0.01 0.01 0.01"/>
      </geometry>
      <material name="grey"/>
    </visual>
    <collision>
      <origin rpy="0 0 0" xyz="0.0 0.0 0.004"/>
      <geometry>
        <box size="0.022 0.032 0.008"/>
      </geometry>
    </collision>
  </link>
  <joint name="crane_plus_shoulder_servo_joint" type="fixed">
    <origin rpy="0 0 0" xyz="-0.0028 0 0.023"/>
    <parent link="crane_plus_base_bracket_link"/>
    <child link="crane_plus_shoulder_servo_link"/>
  </joint>
  <link name="crane_plus_shoulder_servo_link">
    <inertial>
      <mass value="0.00001"/>
      <origin xyz="0 0 0"/>
      <inertia ixx="1.0" ixy="0.0" ixz="0.0" iyy="1.0" iyz="0.0" izz="1.0"/>
    </inertial>
    <visual>
      <origin rpy="-1.570795 0 0" xyz="0 0 0"/>
      <geometry>
        <mesh filename="package://crane_plus_description/meshes/ax12_box.stl" scale="0.001 0.001 0.001"/>
      </geometry>
      <material name="black"/>
    </visual>
    <collision>
      <origin rpy="0 0 0" xyz="0.0015 0 0"/>
      <geometry>
        <box size="0.05 0.032 0.038"/>
      </geometry>
    </collision>
  </link>
  <joint name="crane_plus_shoulder_bracket_rev_joint" type="revolute">
    <origin rpy="0 0 0" xyz="-0.0135 0 0.021"/>
    <axis xyz="0 0 1"/>
    <limit effort="30" lower="-2.617" upper="2.617" velocity="1.571"/>
    <parent link="crane_plus_shoulder_servo_link"/>
    <child link="crane_plus_shoulder_bracket_rev_link"/>
  </joint>
  <link name="crane_plus_shoulder_bracket_rev_link">
    <inertial>
      <mass value="0.00001"/>
      <origin xyz="0 0 0"/>
      <inertia ixx="1.0" ixy="0.0" ixz="0.0" iyy="1.0" iyz="0.0" izz="1.0"/>
    </inertial>
    <visual>
      <origin rpy="1.570795 0 0" xyz="0 0 0.0265"/>
      <geometry>
        <mesh filename="package://crane_plus_description/meshes/f2.stl" scale="0.001 0.001 0.001"/>
      </geometry>
      <material name="grey"/>
    </visual>
    <collision>
      <origin rpy="0 0 0" xyz="0 0 0.01875"/>
      <geometry>
        <box size="0.025 0.0485 0.0375"/>
      </geometry>
    </collision>
  </link>
  <joint name="crane_plus_upper_arm_servo_joint" type="revolute">
    <origin rpy="-1.570795 -1.570795 0" xyz="0 0 0.0265"/>
    <axis xyz="0 0 1"/>
    <limit effort="30" lower="-2.617" upper="2.617" velocity="1.571"/>
    <parent link="crane_plus_shoulder_bracket_rev_link"/>
    <child link="crane_plus_upper_arm_servo_link"/>
  </joint>
  <link name="crane_plus_upper_arm_servo_link">
    <inertial>
      <mass value="0.00001"/>
      <origin xyz="0 0 0"/>
      <inertia ixx="1.0" ixy="0.0" ixz="0.0" iyy="1.0" iyz="0.0" izz="1.0"/>
    </inertial>
    <visual>
      <origin rpy="-1.570795 0 0" xyz="0.012 0 0"/>
      <geometry>
        <mesh filename="package://crane_plus_description/meshes/ax12_box.stl" scale="0.001 0.001 0.001"/>
      </geometry>
      <material name="black"/>
    </visual>
    <collision>
      <origin rpy="0 0 0" xyz="0.0135 0 0"/>
      <geometry>
        <box size="0.05 0.032 0.038"/>
      </geometry>
    </collision>
  </link>
  <joint name="crane_plus_upper_arm_upper_joiner_joint" type="fixed">
    <origin rpy="-1.570795 0 1.570795" xyz="0.0415 0 0"/>
    <parent link="crane_plus_upper_arm_servo_link"/>
    <child link="crane_plus_upper_arm_upper_joiner_link"/>
  </joint>
  <link name="crane_plus_upper_arm_upper_joiner_link">
    <inertial>
      <mass value="0.00001"/>
      <origin xyz="0 0 0"/>
      <inertia ixx="1.0" ixy="0.0" ixz="0.0" iyy="1.0" iyz="0.0" izz="1.0"/>
    </inertial>
    <visual>
      <origin rpy="1.570795 0 3.14159" xyz="0 0 0"/>
      <geometry>
        <mesh filename="package://crane_plus_description/meshes/f3.stl" scale="0.001 0.001 0.001"/>
      </geometry>
      <material name="grey"/>
    </visual>
    <collision>
      <origin rpy="0 0 0" xyz="0.0 0.0 0.0045"/>
      <geometry>
        <box size="0.025 0.038 0.009"/>
      </geometry>
    </collision>
  </link>
  <joint name="crane_plus_upper_arm_lower_joiner_joint" type="fixed">
    <origin rpy="3.14159 0 0" xyz="0 0 0"/>
    <parent link="crane_plus_upper_arm_upper_joiner_link"/>
    <child link="crane_plus_upper_arm_lower_joiner_link"/>
  </joint>
  <link name="crane_plus_upper_arm_lower_joiner_link">
    <inertial>
      <mass value="0.00001"/>
      <origin xyz="0 0 0"/>
      <inertia ixx="1.0" ixy="0.0" ixz="0.0" iyy="1.0" iyz="0.0" izz="1.0"/>
    </inertial>
    <visual>
      <origin rpy="1.570795 0 3.14159" xyz="0 0 0"/>
      <geometry>
        <mesh filename="package://crane_plus_description/meshes/f3.stl" scale="0.001 0.001 0.001"/>
      </geometry>
      <material name="grey"/>
    </visual>
    <collision>
      <origin rpy="0 0 0" xyz="0.0 0.0 0.0045"/>
      <geometry>
        <box size="0.025 0.038 0.009"/>
      </geometry>
    </collision>
  </link>
  <joint name="crane_plus_lower_arm_servo_joint" type="fixed">
    <origin rpy="0 1.570795 1.570795" xyz="0 0 0.0295"/>
    <parent link="crane_plus_upper_arm_lower_joiner_link"/>
    <child link="crane_plus_lower_arm_servo_link"/>
  </joint>
  <link name="crane_plus_lower_arm_servo_link">
    <inertial>
      <mass value="0.00001"/>
      <origin xyz="0 0 0"/>
      <inertia ixx="1.0" ixy="0.0" ixz="0.0" iyy="1.0" iyz="0.0" izz="1.0"/>
    </inertial>
    <visual>
      <origin rpy="-1.570795 0 0" xyz="0 0 0"/>
      <geometry>
        <mesh filename="package://crane_plus_description/meshes/ax12_box.stl" scale="0.001 0.001 0.001"/>
      </geometry>
      <material name="black"/>
    </visual>
    <collision>
      <origin rpy="0 0 0" xyz="0.0015 0 0"/>
      <geometry>
        <box size="0.05 0.032 0.038"/>
      </geometry>
    </collision>
  </link>
  <joint name="crane_plus_lower_arm_bracket_joint" type="revolute">
    <origin rpy="1.570795 0 1.570795" xyz="-0.012 0 0"/>
    <axis xyz="0 1 0"/>
    <limit effort="30" lower="-2.617" upper="2.617" velocity="1.571"/>
    <parent link="crane_plus_lower_arm_servo_link"/>
    <child link="crane_plus_lower_arm_bracket_link"/>
  </joint>
  <link name="crane_plus_lower_arm_bracket_link">
    <inertial>
      <mass value="0.00001"/>
      <origin xyz="0 0 0"/>
      <inertia ixx="1.0" ixy="0.0" ixz="0.0" iyy="1.0" iyz="0.0" izz="1.0"/>
    </inertial>
    <visual>
      <origin rpy="1.570795 0 0" xyz="0 0 0"/>
      <geometry>
        <mesh filename="package://crane_plus_description/meshes/f4.stl" scale="0.001 0.001 0.001"/>
      </geometry>
      <material name="grey"/>
    </visual>
    <collision>
      <!-- 0.0015 is for the nub height which is not included in
             F4_AXLE_HEIGHT -->
      <origin rpy="0 0 0" xyz="0 0 -0.0215"/>
      <geometry>
        <box size="0.028 0.0485 0.065"/>
      </geometry>
    </collision>
  </link>
  <joint name="crane_plus_lower_arm_joiner_joint" type="fixed">
    <origin rpy="0 3.14159 0" xyz="0 0 -0.0525"/>
    <parent link="crane_plus_lower_arm_bracket_link"/>
    <child link="crane_plus_lower_arm_joiner_link"/>
  </joint>
  <link name="crane_plus_lower_arm_joiner_link">
    <inertial>
      <mass value="0.00001"/>
      <origin xyz="0 0 0"/>
      <inertia ixx="1.0" ixy="0.0" ixz="0.0" iyy="1.0" iyz="0.0" izz="1.0"/>
    </inertial>
    <visual>
      <origin rpy="1.570795 0 3.14159" xyz="0 0 0"/>
      <geometry>
        <mesh filename="package://crane_plus_description/meshes/f3.stl" scale="0.001 0.001 0.001"/>
      </geometry>
      <material name="grey"/>
    </visual>
    <collision>
      <origin rpy="0 0 0" xyz="0.0 0.0 0.0045"/>
      <geometry>
        <box size="0.025 0.038 0.009"/>
      </geometry>
    </collision>
  </link>
  <joint name="crane_plus_wrist_servo_joint" type="fixed">
    <origin rpy="0 1.570795 1.570795" xyz="0 0 0.0295"/>
    <parent link="crane_plus_lower_arm_joiner_link"/>
    <child link="crane_plus_wrist_servo_link"/>
  </joint>
  <link name="crane_plus_wrist_servo_link">
    <inertial>
      <mass value="0.00001"/>
      <origin xyz="0 0 0"/>
      <inertia ixx="1.0" ixy="0.0" ixz="0.0" iyy="1.0" iyz="0.0" izz="1.0"/>
    </inertial>
    <visual>
      <origin rpy="-1.570795 0 0" xyz="0 0 0"/>
      <geometry>
        <mesh filename="package://crane_plus_description/meshes/ax12_box.stl" scale="0.001 0.001 0.001"/>
      </geometry>
      <material name="black"/>
    </visual>
    <collision>
      <origin rpy="0 0 0" xyz="0.0015 0 0"/>
      <geometry>
        <box size="0.05 0.032 0.038"/>
      </geometry>
    </collision>
  </link>
  <joint name="crane_plus_wrist_bracket_joint" type="revolute">
    <origin rpy="-1.570795 0 -1.570795" xyz="-0.012 0 0"/>
    <axis xyz="0 1 0"/>
    <limit effort="30" lower="-2.617" upper="2.617" velocity="1.571"/>
    <parent link="crane_plus_wrist_servo_link"/>
    <child link="crane_plus_wrist_bracket_link"/>
  </joint>
  <link name="crane_plus_wrist_bracket_link">
    <inertial>
      <mass value="0.00001"/>
      <origin xyz="0 0 0"/>
      <inertia ixx="1.0" ixy="0.0" ixz="0.0" iyy="1.0" iyz="0.0" izz="1.0"/>
    </inertial>
    <visual>
      <origin rpy="1.570795 0 0" xyz="0 0 0"/>
      <geometry>
        <mesh filename="package://crane_plus_description/meshes/f2.stl" scale="0.001 0.001 0.001"/>
      </geometry>
      <material name="grey"/>
    </visual>
    <collision>
      <origin rpy="0 0 0" xyz="0 0 -0.00775"/>
      <geometry>
        <box size="0.025 0.0485 0.0375"/>
      </geometry>
    </collision>
  </link>
  <joint name="crane_plus_wrist_joiner_joint" type="fixed">
    <origin rpy="0 3.14159 1.570795" xyz="0 0 -0.0265"/>
    <parent link="crane_plus_wrist_bracket_link"/>
    <child link="crane_plus_wrist_joiner_link"/>
  </joint>
  <link name="crane_plus_wrist_joiner_link">
    <inertial>
      <mass value="0.00001"/>
      <origin xyz="0 0 0"/>
      <inertia ixx="1.0" ixy="0.0" ixz="0.0" iyy="1.0" iyz="0.0" izz="1.0"/>
    </inertial>
    <visual>
      <origin rpy="1.570795 0 3.14159" xyz="0 0 0"/>
      <geometry>
        <mesh filename="package://crane_plus_description/meshes/f3.stl" scale="0.001 0.001 0.001"/>
      </geometry>
      <material name="grey"/>
    </visual>
    <collision>
      <origin rpy="0 0 0" xyz="0.0 0.0 0.0045"/>
      <geometry>
        <box size="0.025 0.038 0.009"/>
      </geometry>
    </collision>
  </link>
  <joint name="crane_plus_gripper_servo_joint" type="fixed">
    <origin rpy="1.570795 3.14159 0" xyz="0.0028 0 0.019"/>
    <parent link="crane_plus_wrist_joiner_link"/>
    <child link="crane_plus_gripper_servo_link"/>
  </joint>
  <link name="crane_plus_gripper_servo_link">
    <inertial>
      <mass value="0.00001"/>
      <origin xyz="0 0 0"/>
      <inertia ixx="1.0" ixy="0.0" ixz="0.0" iyy="1.0" iyz="0.0" izz="1.0"/>
    </inertial>
    <visual>
      <origin rpy="-1.570795 0 0" xyz="0 0 0"/>
      <geometry>
        <mesh filename="package://crane_plus_description/meshes/ax12_box.stl" scale="0.001 0.001 0.001"/>
      </geometry>
      <material name="black"/>
    </visual>
    <collision>
      <origin rpy="0 0 0" xyz="0.0015 0 0"/>
      <geometry>
        <box size="0.05 0.032 0.038"/>
      </geometry>
    </collision>
  </link>
  <joint name="crane_plus_fixed_finger_joiner_joint" type="fixed">
    <origin rpy="-1.570795 0 1.570795" xyz="0.0295 0 0"/>
    <parent link="crane_plus_gripper_servo_link"/>
    <child link="crane_plus_fixed_finger_joiner_link"/>
  </joint>
  <link name="crane_plus_fixed_finger_joiner_link">
    <inertial>
      <mass value="0.00001"/>
      <origin xyz="0 0 0"/>
      <inertia ixx="1.0" ixy="0.0" ixz="0.0" iyy="1.0" iyz="0.0" izz="1.0"/>
    </inertial>
    <visual>
      <origin rpy="1.570795 0 3.14159" xyz="0 0 0"/>
      <geometry>
        <mesh filename="package://crane_plus_description/meshes/f3.stl" scale="0.001 0.001 0.001"/>
      </geometry>
      <material name="grey"/>
    </visual>
    <collision>
      <origin rpy="0 0 0" xyz="0.0 0.0 0.0045"/>
      <geometry>
        <box size="0.025 0.038 0.009"/>
      </geometry>
    </collision>
  </link>
  <joint name="crane_plus_fixed_finger_joint" type="fixed">
    <origin rpy="0 0 3.14159" xyz="0 0 0"/>
    <parent link="crane_plus_fixed_finger_joiner_link"/>
    <child link="crane_plus_fixed_finger_link"/>
  </joint>
  <link name="crane_plus_fixed_finger_link">
    <inertial>
      <mass value="0.00001"/>
      <origin xyz="0 0 0"/>
      <inertia ixx="1.0" ixy="0.0" ixz="0.0" iyy="1.0" iyz="0.0" izz="1.0"/>
    </inertial>
    <visual>
      <origin rpy="0 0 0" xyz="0 0 0"/>
      <geometry>
        <mesh filename="package://crane_plus_description/meshes/finger_fixed.stl" scale="0.001 0.001 0.001"/>
      </geometry>
      <material name="black"/>
    </visual>
    <collision>
      <origin rpy="0 0 0" xyz="0 0 0"/>
      <geometry>
        <mesh filename="package://crane_plus_description/meshes/finger_fixed_collision.stl" scale="0.001 0.001 0.001"/>
      </geometry>
    </collision>
  </link>
  <joint name="crane_plus_moving_finger_bracket_joint" type="revolute">
    <origin rpy="-1.570795 0 -1.570795" xyz="-0.012 0 0"/>
    <axis xyz="0 1 0"/>
    <limit effort="30" lower="-2.617" upper="2.617" velocity="1.571"/>
    <parent link="crane_plus_gripper_servo_link"/>
    <child link="crane_plus_moving_finger_bracket_link"/>
  </joint>
  <link name="crane_plus_moving_finger_bracket_link">
    <inertial>
      <mass value="0.00001"/>
      <origin xyz="0 0 0"/>
      <inertia ixx="1.0" ixy="0.0" ixz="0.0" iyy="1.0" iyz="0.0" izz="1.0"/>
    </inertial>
    <visual>
      <origin rpy="1.570795 0 0" xyz="0 0 0"/>
      <geometry>
        <mesh filename="package://crane_plus_description/meshes/f2.stl" scale="0.001 0.001 0.001"/>
      </geometry>
      <material name="grey"/>
    </visual>
    <collision>
      <origin rpy="0 0 0" xyz="0 0 -0.00775"/>
      <geometry>
        <box size="0.025 0.0485 0.0375"/>
      </geometry>
    </collision>
  </link>
  <joint name="crane_plus_moving_finger_joint" type="fixed">
    <origin rpy="3.14159 0 0" xyz="0 0 -0.0265"/>
    <parent link="crane_plus_moving_finger_bracket_link"/>
    <child link="crane_plus_moving_finger_link"/>
  </joint>
  <link name="crane_plus_moving_finger_link">
    <inertial>
      <mass value="0.00001"/>
      <origin xyz="0 0 0"/>
      <inertia ixx="1.0" ixy="0.0" ixz="0.0" iyy="1.0" iyz="0.0" izz="1.0"/>
    </inertial>
    <visual>
      <origin rpy="0 0 0" xyz="0 0 0"/>
      <geometry>
        <mesh filename="package://crane_plus_description/meshes/finger_moving.stl" scale="0.001 0.001 0.001"/>
      </geometry>
      <material name="black"/>
    </visual>
    <collision>
      <origin rpy="0 0 0" xyz="0 0 0"/>
      <geometry>
        <mesh filename="package://crane_plus_description/meshes/finger_moving_collision.stl" scale="0.001 0.001 0.001"/>
      </geometry>
    </collision>
  </link>
</robot>

